WARNING:discord.client:PyNaCl is not installed, voice will NOT be supported
INFO:discord.client:logging in using static token
WARNING:discord.client:PyNaCl is not installed, voice will NOT be supported
INFO:discord.client:logging in using static token
WARNING:discord.client:Application has an interaction endpoint URL set, this means registered components and app commands will not be received by the library.
WARNING:discord.client:PyNaCl is not installed, voice will NOT be supported
INFO:discord.client:logging in using static token
WARNING:discord.client:Application has an interaction endpoint URL set, this means registered components and app commands will not be received by the library.
INFO:discord.gateway:Shard ID None has connected to Gateway (Session ID: c8c71849de0f7bd02837bb0f01d0b229).
INFO:discord.gateway:Shard ID None session has been invalidated.
INFO:discord.gateway:Shard ID None has connected to Gateway (Session ID: 9f6efbed731067b5308850f672b5fe61).
INFO:discord.gateway:Shard ID None session has been invalidated.
INFO:discord.gateway:Shard ID None has connected to Gateway (Session ID: 3983ee3c552744d65573c4bf81fd2826).
INFO:discord.gateway:Shard ID None has successfully RESUMED session 3983ee3c552744d65573c4bf81fd2826.
INFO:discord.gateway:Shard ID None has successfully RESUMED session 3983ee3c552744d65573c4bf81fd2826.
INFO:discord.gateway:Shard ID None session has been invalidated.
INFO:discord.gateway:Shard ID None has connected to Gateway (Session ID: 812289a3eb34ae13655b09ea57f2f017).
INFO:discord.gateway:Shard ID None session has been invalidated.
INFO:discord.gateway:Shard ID None session has been invalidated.
INFO:discord.gateway:Shard ID None session has been invalidated.
INFO:discord.gateway:Shard ID None session has been invalidated.
ERROR:discord.client:Attempting a reconnect in 0.88s
Traceback (most recent call last):
  File "/Library/Frameworks/Python.framework/Versions/3.10/lib/python3.10/site-packages/discord/gateway.py", line 375, in from_client
    socket = await client.http.ws_connect(str(url))
  File "/Library/Frameworks/Python.framework/Versions/3.10/lib/python3.10/site-packages/discord/http.py", line 554, in ws_connect
    return await self.__session.ws_connect(url, **kwargs)
  File "/Library/Frameworks/Python.framework/Versions/3.10/lib/python3.10/site-packages/aiohttp/client.py", line 1004, in _ws_connect
    resp = await self.request(
  File "/Library/Frameworks/Python.framework/Versions/3.10/lib/python3.10/site-packages/aiohttp/client.py", line 730, in _request
    await resp.start(conn)
  File "/Library/Frameworks/Python.framework/Versions/3.10/lib/python3.10/site-packages/aiohttp/client_reqrep.py", line 1059, in start
    message, payload = await protocol.read()  # type: ignore[union-attr]
  File "/Library/Frameworks/Python.framework/Versions/3.10/lib/python3.10/site-packages/aiohttp/streams.py", line 672, in read
    await self._waiter
asyncio.exceptions.CancelledError

During handling of the above exception, another exception occurred:

Traceback (most recent call last):
  File "/Library/Frameworks/Python.framework/Versions/3.10/lib/python3.10/asyncio/tasks.py", line 456, in wait_for
    return fut.result()
asyncio.exceptions.CancelledError

The above exception was the direct cause of the following exception:

Traceback (most recent call last):
  File "/Library/Frameworks/Python.framework/Versions/3.10/lib/python3.10/site-packages/discord/client.py", line 701, in connect
    self.ws = await asyncio.wait_for(coro, timeout=60.0)
  File "/Library/Frameworks/Python.framework/Versions/3.10/lib/python3.10/asyncio/tasks.py", line 458, in wait_for
    raise exceptions.TimeoutError() from exc
asyncio.exceptions.TimeoutError
ERROR:discord.client:Attempting a reconnect in 0.81s
Traceback (most recent call last):
  File "/Library/Frameworks/Python.framework/Versions/3.10/lib/python3.10/site-packages/discord/gateway.py", line 375, in from_client
    socket = await client.http.ws_connect(str(url))
  File "/Library/Frameworks/Python.framework/Versions/3.10/lib/python3.10/site-packages/discord/http.py", line 554, in ws_connect
    return await self.__session.ws_connect(url, **kwargs)
  File "/Library/Frameworks/Python.framework/Versions/3.10/lib/python3.10/site-packages/aiohttp/client.py", line 1004, in _ws_connect
    resp = await self.request(
  File "/Library/Frameworks/Python.framework/Versions/3.10/lib/python3.10/site-packages/aiohttp/client.py", line 730, in _request
    await resp.start(conn)
  File "/Library/Frameworks/Python.framework/Versions/3.10/lib/python3.10/site-packages/aiohttp/client_reqrep.py", line 1059, in start
    message, payload = await protocol.read()  # type: ignore[union-attr]
  File "/Library/Frameworks/Python.framework/Versions/3.10/lib/python3.10/site-packages/aiohttp/streams.py", line 672, in read
    await self._waiter
asyncio.exceptions.CancelledError

During handling of the above exception, another exception occurred:

Traceback (most recent call last):
  File "/Library/Frameworks/Python.framework/Versions/3.10/lib/python3.10/asyncio/tasks.py", line 456, in wait_for
    return fut.result()
asyncio.exceptions.CancelledError

The above exception was the direct cause of the following exception:

Traceback (most recent call last):
  File "/Library/Frameworks/Python.framework/Versions/3.10/lib/python3.10/site-packages/discord/client.py", line 701, in connect
    self.ws = await asyncio.wait_for(coro, timeout=60.0)
  File "/Library/Frameworks/Python.framework/Versions/3.10/lib/python3.10/asyncio/tasks.py", line 458, in wait_for
    raise exceptions.TimeoutError() from exc
asyncio.exceptions.TimeoutError
INFO:discord.gateway:Shard ID None session has been invalidated.
INFO:discord.gateway:Shard ID None session has been invalidated.
INFO:discord.gateway:Shard ID None session has been invalidated.
INFO:discord.gateway:Shard ID None has connected to Gateway (Session ID: 19c3d1bc2d1e688d32fc2bb370e1f612).
INFO:discord.gateway:Shard ID None session has been invalidated.
INFO:discord.gateway:Shard ID None session has been invalidated.
INFO:discord.gateway:Shard ID None session has been invalidated.
INFO:discord.gateway:Shard ID None session has been invalidated.
INFO:discord.gateway:Shard ID None session has been invalidated.
INFO:discord.gateway:Shard ID None session has been invalidated.
INFO:discord.gateway:Shard ID None session has been invalidated.
INFO:discord.gateway:Shard ID None session has been invalidated.
INFO:discord.gateway:Shard ID None has connected to Gateway (Session ID: e0221234ce8c26f02c0af9747b16bda9).
ERROR:discord.client:Ignoring exception in on_message
Traceback (most recent call last):
  File "/Library/Frameworks/Python.framework/Versions/3.10/lib/python3.10/site-packages/discord/client.py", line 481, in _run_event
    await coro(*args, **kwargs)
  File "/Users/avinash/mcp-discord-bot/bot.py", line 30, in on_message
    # Apply transformations
  File "/Users/avinash/mcp-discord-bot/utils.py", line 4, in load_rules
FileNotFoundError: [Errno 2] No such file or directory: 'rules.json'
ERROR:discord.client:Ignoring exception in on_message
Traceback (most recent call last):
  File "/Library/Frameworks/Python.framework/Versions/3.10/lib/python3.10/site-packages/discord/client.py", line 481, in _run_event
    await coro(*args, **kwargs)
  File "/Users/avinash/mcp-discord-bot/bot.py", line 30, in on_message
    # Apply transformations
  File "/Users/avinash/mcp-discord-bot/utils.py", line 4, in load_rules
FileNotFoundError: [Errno 2] No such file or directory: 'rules.json'
ERROR:discord.client:Ignoring exception in on_message
Traceback (most recent call last):
  File "/Library/Frameworks/Python.framework/Versions/3.10/lib/python3.10/site-packages/discord/client.py", line 481, in _run_event
    await coro(*args, **kwargs)
  File "/Users/avinash/mcp-discord-bot/bot.py", line 30, in on_message
    # Apply transformations
  File "/Users/avinash/mcp-discord-bot/utils.py", line 4, in load_rules
FileNotFoundError: [Errno 2] No such file or directory: 'rules.json'
ERROR:discord.client:Ignoring exception in on_message
Traceback (most recent call last):
  File "/Library/Frameworks/Python.framework/Versions/3.10/lib/python3.10/site-packages/discord/client.py", line 481, in _run_event
    await coro(*args, **kwargs)
  File "/Users/avinash/mcp-discord-bot/bot.py", line 30, in on_message
    # Apply transformations
  File "/Users/avinash/mcp-discord-bot/utils.py", line 4, in load_rules
FileNotFoundError: [Errno 2] No such file or directory: 'rules.json'
ERROR:discord.client:Ignoring exception in on_message
Traceback (most recent call last):
  File "/Library/Frameworks/Python.framework/Versions/3.10/lib/python3.10/site-packages/discord/client.py", line 481, in _run_event
    await coro(*args, **kwargs)
  File "/Users/avinash/mcp-discord-bot/bot.py", line 30, in on_message
    # Apply transformations
  File "/Users/avinash/mcp-discord-bot/utils.py", line 4, in load_rules
FileNotFoundError: [Errno 2] No such file or directory: 'rules.json'
ERROR:discord.client:Ignoring exception in on_message
Traceback (most recent call last):
  File "/Library/Frameworks/Python.framework/Versions/3.10/lib/python3.10/site-packages/discord/client.py", line 481, in _run_event
    await coro(*args, **kwargs)
  File "/Users/avinash/mcp-discord-bot/bot.py", line 30, in on_message
    # Apply transformations
  File "/Users/avinash/mcp-discord-bot/utils.py", line 4, in load_rules
FileNotFoundError: [Errno 2] No such file or directory: 'rules.json'
ERROR:discord.client:Ignoring exception in on_message
Traceback (most recent call last):
  File "/Library/Frameworks/Python.framework/Versions/3.10/lib/python3.10/site-packages/discord/client.py", line 481, in _run_event
    await coro(*args, **kwargs)
  File "/Users/avinash/mcp-discord-bot/bot.py", line 30, in on_message
    # Apply transformations
  File "/Users/avinash/mcp-discord-bot/utils.py", line 4, in load_rules
FileNotFoundError: [Errno 2] No such file or directory: 'rules.json'
ERROR:discord.client:Ignoring exception in on_message
Traceback (most recent call last):
  File "/Library/Frameworks/Python.framework/Versions/3.10/lib/python3.10/site-packages/discord/client.py", line 481, in _run_event
    await coro(*args, **kwargs)
  File "/Users/avinash/mcp-discord-bot/bot.py", line 30, in on_message
    # Apply transformations
  File "/Users/avinash/mcp-discord-bot/utils.py", line 4, in load_rules
FileNotFoundError: [Errno 2] No such file or directory: 'rules.json'
ERROR:discord.client:Ignoring exception in on_message
Traceback (most recent call last):
  File "/Library/Frameworks/Python.framework/Versions/3.10/lib/python3.10/site-packages/discord/client.py", line 481, in _run_event
    await coro(*args, **kwargs)
  File "/Users/avinash/mcp-discord-bot/bot.py", line 30, in on_message
    # Apply transformations
  File "/Users/avinash/mcp-discord-bot/utils.py", line 4, in load_rules
FileNotFoundError: [Errno 2] No such file or directory: 'rules.json'
ERROR:discord.client:Ignoring exception in on_message
Traceback (most recent call last):
  File "/Library/Frameworks/Python.framework/Versions/3.10/lib/python3.10/site-packages/discord/client.py", line 481, in _run_event
    await coro(*args, **kwargs)
  File "/Users/avinash/mcp-discord-bot/bot.py", line 30, in on_message
    # Apply transformations
  File "/Users/avinash/mcp-discord-bot/utils.py", line 4, in load_rules
FileNotFoundError: [Errno 2] No such file or directory: 'rules.json'
ERROR:discord.client:Ignoring exception in on_message
Traceback (most recent call last):
  File "/Library/Frameworks/Python.framework/Versions/3.10/lib/python3.10/site-packages/discord/client.py", line 481, in _run_event
    await coro(*args, **kwargs)
  File "/Users/avinash/mcp-discord-bot/bot.py", line 30, in on_message
    # Apply transformations
  File "/Users/avinash/mcp-discord-bot/utils.py", line 4, in load_rules
FileNotFoundError: [Errno 2] No such file or directory: 'rules.json'
ERROR:discord.client:Ignoring exception in on_message
Traceback (most recent call last):
  File "/Library/Frameworks/Python.framework/Versions/3.10/lib/python3.10/site-packages/discord/client.py", line 481, in _run_event
    await coro(*args, **kwargs)
  File "/Users/avinash/mcp-discord-bot/bot.py", line 30, in on_message
    # Apply transformations
  File "/Users/avinash/mcp-discord-bot/utils.py", line 4, in load_rules
FileNotFoundError: [Errno 2] No such file or directory: 'rules.json'
ERROR:discord.client:Ignoring exception in on_message
Traceback (most recent call last):
  File "/Library/Frameworks/Python.framework/Versions/3.10/lib/python3.10/site-packages/discord/client.py", line 481, in _run_event
    await coro(*args, **kwargs)
  File "/Users/avinash/mcp-discord-bot/bot.py", line 30, in on_message
    # Apply transformations
  File "/Users/avinash/mcp-discord-bot/utils.py", line 4, in load_rules
FileNotFoundError: [Errno 2] No such file or directory: 'rules.json'
ERROR:discord.client:Ignoring exception in on_message
Traceback (most recent call last):
  File "/Library/Frameworks/Python.framework/Versions/3.10/lib/python3.10/site-packages/discord/client.py", line 481, in _run_event
    await coro(*args, **kwargs)
  File "/Users/avinash/mcp-discord-bot/bot.py", line 30, in on_message
    # Apply transformations
  File "/Users/avinash/mcp-discord-bot/utils.py", line 4, in load_rules
FileNotFoundError: [Errno 2] No such file or directory: 'rules.json'
ERROR:discord.client:Ignoring exception in on_message
Traceback (most recent call last):
  File "/Library/Frameworks/Python.framework/Versions/3.10/lib/python3.10/site-packages/discord/client.py", line 481, in _run_event
    await coro(*args, **kwargs)
  File "/Users/avinash/mcp-discord-bot/bot.py", line 30, in on_message
    # Apply transformations
  File "/Users/avinash/mcp-discord-bot/utils.py", line 4, in load_rules
FileNotFoundError: [Errno 2] No such file or directory: 'rules.json'
ERROR:discord.client:Ignoring exception in on_message
Traceback (most recent call last):
  File "/Library/Frameworks/Python.framework/Versions/3.10/lib/python3.10/site-packages/discord/client.py", line 481, in _run_event
    await coro(*args, **kwargs)
  File "/Users/avinash/mcp-discord-bot/bot.py", line 30, in on_message
    # Apply transformations
  File "/Users/avinash/mcp-discord-bot/utils.py", line 4, in load_rules
FileNotFoundError: [Errno 2] No such file or directory: 'rules.json'
